Workbook
Name _2__Adequate_ethane___methane_signal?: [1]AllSites!$BH$2:$BH$1048576
Name _3__Good_ethane___methane_correlation?: [1]AllSites!$BI$2:$BI$1048576
Name _4__Good_tracer_correlation?: [1]AllSites!$BM$2:$BM$1048576
Name _5__Good_tracer_ratio?: [1]AllSites!$BO$2:$BO$1048576
Name _6a__Good_acetylene_methane_correlation?: [1]AllSites!$BQ$2:$BQ$1048576
Name _6b__Good_nitrous_methane_correlation?: [1]AllSites!$BR$2:$BR$1048576
Name _7__Good_tracer_area_ratio?: [1]AllSites!$BU$2:$BU$1048576
Name _c2h2_area: [1]AllSites!$AN$2:$AN$1048576
Name _c2h2_flow: [1]AllSites!$J$2:$J$1048576
Name _Ref79413875: #REF!
Name _Ref79414097: #REF!
Name _Ref79414132: #REF!
Name A: '[2]National account cube'!$B$1:$B$10,'[2]National account cube'!$B$12:$B$224
Name A1828364K: '[3]exp 12b Data1'!$B$1:$B$10,'[3]exp 12b Data1'!$B$11:$B$388
Name A1828365L: '[3]exp 12b Data1'!$C$1:$C$10,'[3]exp 12b Data1'!$C$11:$C$388
Name A1828366R: '[3]exp 12b Data1'!$D$1:$D$10,'[3]exp 12b Data1'!$D$11:$D$388
Name A1828367T: '[3]exp 12b Data1'!$E$1:$E$10,'[3]exp 12b Data1'!$E$11:$E$388
Name A1828368V: '[3]exp 12b Data1'!$F$1:$F$10,'[3]exp 12b Data1'!$F$11:$F$388
Name A1828369W: '[3]exp 12b Data1'!$G$1:$G$10,'[3]exp 12b Data1'!$G$11:$G$388
Name A1828370F: '[3]exp 12b Data1'!$H$1:$H$10,'[3]exp 12b Data1'!$H$11:$H$388
Name A1828371J: '[3]exp 12b Data1'!$I$1:$I$10,'[3]exp 12b Data1'!$I$11:$I$388
Name A1828372K: '[3]exp 12b Data1'!$J$1:$J$10,'[3]exp 12b Data1'!$J$11:$J$388
Name A1828373L: '[3]exp 12b Data1'!$K$1:$K$10,'[3]exp 12b Data1'!$K$11:$K$388
Name A1828374R: '[3]exp 12b Data1'!$L$1:$L$10,'[3]exp 12b Data1'!$L$11:$L$388
Name A1828375T: '[3]exp 12b Data1'!$M$1:$M$10,'[3]exp 12b Data1'!$M$11:$M$388
Name A1828376V: '[3]exp 12b Data1'!$N$1:$N$10,'[3]exp 12b Data1'!$N$11:$N$388
Name A1828377W: '[3]exp 12b Data1'!$O$1:$O$10,'[3]exp 12b Data1'!$O$11:$O$388
Name A1828378X: '[3]exp 12b Data1'!$P$1:$P$10,'[3]exp 12b Data1'!$P$11:$P$388
Name A1828379A: '[3]exp 12b Data1'!$Q$1:$Q$10,'[3]exp 12b Data1'!$Q$11:$Q$388
Name A1828380K: '[3]exp 12b Data1'!$R$1:$R$10,'[3]exp 12b Data1'!$R$11:$R$388
Name A1828381L: '[3]exp 12b Data1'!$S$1:$S$10,'[3]exp 12b Data1'!$S$11:$S$388
Name A1828382R: '[3]exp 12b Data1'!$T$1:$T$10,'[3]exp 12b Data1'!$T$11:$T$388
Name A1828383T: '[3]exp 12b Data1'!$U$1:$U$10,'[3]exp 12b Data1'!$U$11:$U$388
Name A1828384V: '[3]exp 12b Data1'!$V$1:$V$10,'[3]exp 12b Data1'!$V$11:$V$388
Name A1828385W: '[3]exp 12b Data1'!$W$1:$W$10,'[3]exp 12b Data1'!$W$11:$W$388
Name A1828386X: '[3]exp 12b Data1'!$X$1:$X$10,'[3]exp 12b Data1'!$X$11:$X$388
Name A1828387A: '[3]exp 12b Data1'!$Y$1:$Y$10,'[3]exp 12b Data1'!$Y$11:$Y$388
Name A1828388C: '[3]exp 12b Data1'!$Z$1:$Z$10,'[3]exp 12b Data1'!$Z$11:$Z$388
Name A1828389F: '[3]exp 12b Data1'!$AA$1:$AA$10,'[3]exp 12b Data1'!$AA$11:$AA$388
Name A1828390R: '[3]exp 12b Data1'!$AB$1:$AB$10,'[3]exp 12b Data1'!$AB$11:$AB$388
Name A1828391T: '[3]exp 12b Data1'!$AC$1:$AC$10,'[3]exp 12b Data1'!$AC$11:$AC$388
Name A1828392V: '[3]exp 12b Data1'!$AD$1:$AD$10,'[3]exp 12b Data1'!$AD$11:$AD$388
Name A1828393W: '[3]exp 12b Data1'!$AE$1:$AE$10,'[3]exp 12b Data1'!$AE$11:$AE$388
Name A1828394X: '[3]exp 12b Data1'!$AF$1:$AF$10,'[3]exp 12b Data1'!$AF$11:$AF$388
Name A1828395A: '[3]exp 12b Data1'!$AG$1:$AG$10,'[3]exp 12b Data1'!$AG$11:$AG$388
Name A1828396C: '[3]exp 12b Data1'!$AH$1:$AH$10,'[3]exp 12b Data1'!$AH$11:$AH$388
Name A1828397F: '[3]exp 12b Data1'!$AI$1:$AI$10,'[3]exp 12b Data1'!$AI$11:$AI$388
Name A1828398J: '[3]exp 12b Data1'!$AJ$1:$AJ$10,'[3]exp 12b Data1'!$AJ$11:$AJ$388
Name A1828399K: '[3]exp 12b Data1'!$AK$1:$AK$10,'[3]exp 12b Data1'!$AK$11:$AK$388
Name A1828400J: '[3]exp 12b Data1'!$AL$1:$AL$10,'[3]exp 12b Data1'!$AL$11:$AL$388
Name A1828401K: '[3]exp 12b Data1'!$AM$1:$AM$10,'[3]exp 12b Data1'!$AM$11:$AM$388
Name A1828402L: '[3]exp 12b Data1'!$AN$1:$AN$10,'[3]exp 12b Data1'!$AN$11:$AN$388
Name A1828403R: '[3]exp 12b Data1'!$AO$1:$AO$10,'[3]exp 12b Data1'!$AO$11:$AO$388
Name A1828404T: '[3]exp 12b Data1'!$AP$1:$AP$10,'[3]exp 12b Data1'!$AP$11:$AP$388
Name A1828405V: '[3]exp 12b Data1'!$AQ$1:$AQ$10,'[3]exp 12b Data1'!$AQ$11:$AQ$388
Name A1828406W: '[3]exp 12b Data1'!$AR$1:$AR$10,'[3]exp 12b Data1'!$AR$11:$AR$388
Name A1828407X: '[3]exp 12b Data1'!$AS$1:$AS$10,'[3]exp 12b Data1'!$AS$11:$AS$388
Name A1828408A: '[3]exp 12b Data1'!$AT$1:$AT$10,'[3]exp 12b Data1'!$AT$11:$AT$388
Name A1828409C: '[3]exp 12b Data1'!$AU$1:$AU$10,'[3]exp 12b Data1'!$AU$11:$AU$388
Name A1828410L: '[3]exp 12b Data1'!$AV$1:$AV$10,'[3]exp 12b Data1'!$AV$11:$AV$388

Sheet Front Cover

Sheet Copyright

Sheet Contents
A1: Quarterly Update of Australia's National Greenhouse Gas Inventory
A2: Figures and Tables for the December Quarter 2025
A3: Published by the Department of Climate Change, Energy, the Environment and Water, 2026
A5: Contents
A6: Figures
A7: ='Figure P1'!A4 -> Figure P1: Emissions, by quarter, September 2004 to December 2025 (including preliminary March 2026)
A8: ='Figure 1'!A4 -> Figure 1: Emissions, by quarter, September 2004 to December 2025
A9: ='Figure 2'!A4 -> Figure 2: Emissions by quarter and gas, trend, September 2004 to December 2025
A10: ='Figure 3'!A4 -> Figure 3: Change in emissions from year to December 2024 to year to December 2025 by sector, Mt CO2-e.
A11: ='Figure 4'!A4 -> Figure 4: Percentage change in emissions, by sector, since year to June 2005
A12: ='Figure 4a'!A4 -> Figure 4a: Percentage change in emissions, by sector, since year to December 2025 (excluding LULUCF)
A13: ='Figure 5'!A4 -> Figure 5: Share of total emissions, by sector, for the year to December 2025
A14: ='Figure 5'!A4 -> Figure 5: Share of total emissions, by sector, for the year to December 2025
A15: ='Figure 6'!A4 -> Figure 6: Emissions from the electricity sector, by quarter, September 2004 to December 2025
A16: ='Figure 7'!A4 -> Figure7: NEM emissions, by quarter, September 2004 to December 2025 (including preliminary March 2026)
A17: ='Figure 8'!$A$4 -> Figure 8: Change in electricity generation in the NEM (trend), by fuel, by quarter, September 2010 to December 2025 (including preliminary March 2026)
A18: ='Figure 9'!$A$4 -> Figure 9: Stationary energy excluding electricity emissions and energy industries excluding electricity, by quarter, September 2004 to December 2025
A19: ='Figure 10'!$A$4 -> Figure 10: LNG exports, by quarter, September 2004 to December 2025
A20: ='Figure 11'!$A$4 -> Figure 11: Transport emissions, actual and trend, by quarter, September 2004 to December 2025
A21: ='Figure 12'!$A$4 -> Figure 12: Consumption of primary liquid fuels, actual and trend, by quarter, June 2005 to December 2025
A22: ='Figure 13'!$A$4 -> Figure 13: Fugitive emissions, actual and trend, by sub-sector, by quarter September 2004 to December 2025
A23: ='Figure 14'!$A$4 -> Figure 14: Industrial processes and product use emissions, actual, by sub-sector, by quarter, September 2004 to December 2025
A24: ='Figure 15'!$A$4 -> Figure 15: Agriculture emissions, actual and trend, by quarter, September 2004 to December 2025
A25: ='Figure 16'!$A$4 -> Figure 16: Waste emissions, actual, by sub-sector, by quarter, September 2004 to December 2025
A26: ='Figure 17'!$A$4 -> Figure 17: LULUCF net anthropogenic emissions, by sub-sector, from year to December 2025
A27: ='Figure 18'!$A$4 -> Figure 18: Emissions per capita and per dollar of real GDP, by quarter, September 2004 to December 2025
A28: ='Figure ST1'!$A$4 -> Figure ST1: Total cleared area, Australia, 1989-90 to 2023-24
A29: ='Figure ST2'!$A$4 -> Figure ST2: Disaggregated emissions associated with forest conversions
A30: ='Figure ST3'!$A$4 -> Figure ST3: Net emissions from regrowth and regenerating forest
A31: ='Figure ST4'!$A$4 -> Figure ST4: Harvest Area and Net Emissions in Harvested Native Forests
A32: ='Figure ST5'!$A$4 -> Figure ST5: Net emissions from savanna fire management in ACCU project areas and non-project areas
A33: Tables
A34: ='Data Table 1A'!A4 -> Data Table 1A: Actual emissions (Mt), by sector, by quarter, since 2004-05 (including preliminary March 2026)
A35: ='Data Table 1B'!A4 -> Data Table 1B: Seasonally adjusted emissions (Mt), by sector, by quarter, since 2004-05 (including preliminary March 2026)
A36: ='Data Table 1C'!A4 -> Data Table 1C: Trend emissions (Mt), by sector, by quarter, since 2004-05 (including preliminary March 2026)
A38: dcceew.gov.au

Sheet Figure P1
A1: Quarterly Update of Australia's National Greenhouse Gas Inventory | Figures and Tables for the December Quarter 2025
A2: Click here to return to contents page
A4: Figure P1: Emissions, by quarter, September 2004 to December 2025 (including preliminary March 2026)
A5: Units: | B5: Million tonnes of carbon dioxide equivalent | C5: Million tonnes of carbon dioxide equivalent
A6: Quarter | B6: Seasonally adjusted and weather normalised | C6: Trend
A7: 38231 | B7: 151.18156 | C7: 149.83459
A8: 38322 | B8: 151.65293 | C8: 151.63018
A9: 38412 | B9: 153.2081 | C9: 153.45096
A10: 38504 | B10: 151.62363 | C10: 155.89573
A11: 38596 | B11: 160.95529 | C11: 158.72276
A12: 38687 | B12: 161.1653 | C12: 160.85918
A13: 38777 | B13: 161.43692 | C13: 161.24475
A14: 38869 | B14: 160.40122 | C14: 159.96451
A15: 38961 | B15: 156.96805 | C15: 158.21129
A16: 39052 | B16: 156.8457 | C16: 156.99278
A17: 39142 | B17: 156.71868 | C17: 156.42007
A18: 39234 | B18: 155.95253 | C18: 155.89955
... A93: 46082 | B93: 113.36971 | C93: 113.99608
A95: Source: Department of Climate Change, Energy, the Environment and Water

Sheet Figure 1
A1: Quarterly Update of Australia's National Greenhouse Gas Inventory | Figures and Tables for the December Quarter 2025
A2: Click here to return to contents page
A4: Figure 1: Emissions, by quarter, September 2004 to December 2025
A5: Units: | B5: Million tonnes of carbon dioxide equivalent | C5: Million tonnes of carbon dioxide equivalent | D5: Million tonnes of carbon dioxide equivalent
A6: Quarter | B6: Actual emissions | C6: Seasonally adjusted and weather normalised | D6: Trend
A7: 38231 | B7: 156.2807 | C7: 151.18156 | D7: 149.83459
A8: 38322 | B8: 148.93172 | C8: 151.65293 | D8: 151.63018
A9: 38412 | B9: 148.40287 | C9: 153.2081 | D9: 153.45096
A10: 38504 | B10: 154.11395 | C10: 151.62363 | D10: 155.89573
A11: 38596 | B11: 165.97847 | C11: 160.95529 | D11: 158.72276
A12: 38687 | B12: 158.3142 | C12: 161.1653 | D12: 160.85918
A13: 38777 | B13: 156.79172 | C13: 161.43692 | D13: 161.24475
A14: 38869 | B14: 163.00165 | C14: 160.40122 | D14: 159.96451
A15: 38961 | B15: 161.82238 | C15: 156.96805 | D15: 158.21129
A16: 39052 | B16: 153.8843 | C16: 156.8457 | D16: 156.99278
A17: 39142 | B17: 152.24585 | C17: 156.71868 | D17: 156.42007
A18: 39234 | B18: 158.82227 | C18: 155.95253 | D18: 155.89955
... A92: 45992 | B92: 111.33423 | C92: 114.24824 | D92: 114.37525
A95: Source: Department of Climate Change, Energy, the Environment and Water

Sheet Figure 2
A1: ='Figure P1'!A1 -> Quarterly Update of Australia's National Greenhouse Gas Inventory | Figures and Tables for the December Quarter 2025
A2: Click here to return to contents page
A4: Figure 2: Emissions by quarter and gas, trend, September 2004 to December 2025
A6: Units: | B6: Million tonnes of carbon dioxide equivalent
B7: Carbon dioxide equivalent (CO2-e) | F7: Raw gas (CO2, CH4 and N2O)
A8: Quarter | B8: CO2 emissions (trend) | C8: CH4 emissions (trend) | D8: N2O emissions (trend) | E8: Other emissions (trend) | F8: Raw CO2 emissions (trend) | G8: Raw CH4 emissions (trend) | H8: Raw N2O emissions (trend)
A9: 38231 | B9: 106.72881 | C9: 36.655414 | D9: 5.0787833 | E9: 1.3116955 | F9: 108.80255 | G9: 1.3077707 | H9: 0.019181622
A10: 38322 | B10: 108.54343 | C10: 36.6348 | D10: 5.0787954 | E10: 1.3614862 | F10: 108.7807 | G10: 1.3089083 | H10: 0.01917935
A11: 38412 | B11: 110.45938 | C11: 36.703734 | D11: 5.0857559 | E11: 1.368755 | F11: 109.72021 | G11: 1.3111661 | H11: 0.01919066
A12: 38504 | B12: 113.0157 | C12: 36.80281 | D12: 5.1012567 | E12: 1.3295189 | F12: 112.00331 | G12: 1.3143406 | H12: 0.019240691
A13: 38596 | B13: 115.82583 | C13: 36.903118 | D13: 5.1211434 | E13: 1.2718146 | F13: 114.93893 | G13: 1.3179546 | H13: 0.019321606
A14: 38687 | B14: 117.79654 | C14: 36.955241 | D14: 5.1286684 | E14: 1.2344965 | F14: 117.2112 | G14: 1.3199634 | H14: 0.019361019
A15: 38777 | B15: 118.02117 | C15: 36.985826 | D15: 5.1105746 | E15: 1.2363838 | F15: 117.70283 | G15: 1.3212037 | H15: 0.019291964
A16: 38869 | B16: 116.68489 | C16: 37.056753 | D16: 5.068566 | E16: 1.2676654 | F16: 116.4386 | G16: 1.3236762 | H16: 0.019124248
A17: 38961 | B17: 114.88405 | C17: 37.210627 | D17: 5.0159599 | E17: 1.3058451 | F17: 114.57119 | G17: 1.3292212 | H17: 0.018926281
A18: 39052 | B18: 113.48713 | C18: 37.385643 | D18: 4.9740636 | E18: 1.3384159 | F18: 113.16649 | G18: 1.3355877 | H18: 0.018779027
A19: 39142 | B19: 112.75817 | C19: 37.438632 | D19: 4.9416033 | E19: 1.3664903 | F19: 112.54472 | G19: 1.3377796 | H19: 0.018666245
A20: 39234 | B20: 112.31288 | C20: 37.252088 | D20: 4.9051986 | E20: 1.391048 | F20: 112.30793 | G20: 1.3313463 | H20: 0.01852883
... A94: 45992 | B94: 75.304929 | C94: 31.114696 | D94: 5.0170108 | E94: 2.8522252 | F94: 75.569336 | G94: 1.1113137 | H94: 0.018932736
A96: Note: Raw gas numbers may not convert directly to CO2-e numbers as data is trended.
A97: Source: Department of Climate Change, Energy, the Environment and Water

Sheet Figure 3
A1: ='Figure 2'!A1 -> Quarterly Update of Australia's National Greenhouse Gas Inventory | Figures and Tables for the December Quarter 2025
A2: Click here to return to contents page
A4: Figure 3: Change in emissions from year to December 2024 to year to December 2025 by sector, Mt CO2-e.
A5: Units: | B5: Mt CO2-e
B6: Change | C6: ABS Change | D6: Inventory total | E6: Sub total
A7: Year to September 2024 | D7: 520.71749 | E7: 520.71749
A8: Electricity | B8: -5.7261199 | C8: 5.7261199 | D8: 514.99137 | E8: 514.99137
A9: Fugitives | B9: -2.5192348 | C9: 2.5192348 | D9: 512.47214 | E9: 512.47214
A10: Stationary Energy | B10: -1.5284651 | C10: 1.5284651 | D10: 510.94367 | E10: 510.94367
A11: Transport | B11: -0.62924127 | C11: 0.62924127 | D11: 510.31443 | E11: 510.31443
A12: Waste | B12: -0.23941661 | C12: 0.23941661 | D12: 510.07501 | E12: 510.07501
A13: Agriculture | B13: -0.076267165 | C13: 0.076267165 | D13: 509.99875 | E13: 509.99875
A14: IPPU | B14: 0.91461386 | C14: 0.91461386 | D14: 509.99875 | E14: 510.91336
A15: Year to September 2025 | D15: 510.91336
A17: Source: Department of Climate Change, Energy, the Environment and Water

Sheet Figure 4
A1: ='Figure 2'!A1 -> Quarterly Update of Australia's National Greenhouse Gas Inventory | Figures and Tables for the December Quarter 2025
A2: Click here to return to contents page
A4: Figure 4: Percentage change in emissions, by sector, since year to June 2005
A5: Units: | B5: % change
A6: Year | B6: Electricity | C6: Stationary energy excl. electricity | D6: Transport | E6: Fugitive emissions | F6: Industrial processes and product use | G6: Agriculture | H6: Waste | I6: LULUCF
A7: 2005 | B7: 0 | C7: 0 | D7: 0 | E7: 0 | F7: 0 | G7: 0 | H7: 0 | I7: 0
A8: 2006 | B8: 0.031 | C8: -0.001 | D8: 0.027 | E8: 0.059 | F8: 0.05 | G8: -0.036 | H8: -0.003 | I8: 0.242
A9: 2007 | B9: 0.04 | C9: 0.02 | D9: 0.049 | E9: 0.103 | F9: 0.082 | G9: -0.074 | H9: 0.025 | I9: -0.009
A10: 2008 | B10: 0.058 | C10: 0.04 | D10: 0.061 | E10: 0.08 | F10: 0.087 | G10: -0.088 | H10: 0.038 | I10: -0.141
A11: 2009 | B11: 0.059 | C11: 0.001 | D11: 0.072 | E11: 0.067 | F11: 0.012 | G11: -0.104 | H11: 0.027 | I11: -0.15
A12: 2010 | B12: 0.026 | C12: 0.04 | D12: 0.096 | E12: 0.061 | F12: 0.14 | G12: -0.092 | H12: 0.008 | I12: -0.323
A13: 2011 | B13: 0.017 | C13: 0.07 | D13: 0.116 | E13: 0.042 | F13: 0.11 | G13: -0.06 | H13: -0.05 | I13: -0.713
A14: 2012 | B14: -0.024 | C14: 0.107 | D14: 0.125 | E14: 0.06 | F14: 0.013 | G14: -0.048 | H14: -0.104 | I14: -0.82
A15: 2013 | B15: -0.071 | C15: 0.148 | D15: 0.139 | E15: 0.05 | F15: -0.011 | G15: -0.046 | H15: -0.131 | I15: -0.823
A16: 2014 | B16: -0.053 | C16: 0.107 | D16: 0.145 | E16: 0.091 | F16: -0.003 | G16: -0.062 | H16: -0.124 | I16: -0.98
A17: 2015 | B17: -0.024 | C17: 0.105 | D17: 0.167 | E17: 0.179 | F17: 0.017 | G17: -0.089 | H17: -0.093 | I17: -1.4
A18: 2016 | B18: -0.034 | C18: 0.128 | D18: 0.168 | E18: 0.244 | F18: 0.029 | G18: -0.069 | H18: -0.081 | I18: -1.534
... A26: 2024 | B26: -0.229 | C26: 0.213 | D26: 0.24 | E26: 0.136 | F26: 0.021 | G26: -0.078 | H26: -0.129 | I26: -1.679
A27: 2025 | B27: -0.258 | C27: 0.194 | D27: 0.233 | E27: 0.077 | F27: 0.051 | G27: -0.078 | H27: -0.144 | I27: -1.677
A29: Source: Department of Climate Change, Energy, the Environment and Water

Sheet Figure 4a
A1: ='Figure 2'!A1 -> Quarterly Update of Australia's National Greenhouse Gas Inventory | Figures and Tables for the December Quarter 2025
A2: Click here to return to contents page
A4: Figure 4a: Percentage change in emissions, by sector, since year to December 2025 (excluding LULUCF)
A5: Units: | B5: % change
A6: Year | B6: Electricity | C6: Stationary energy excl. electricity | D6: Transport | E6: Fugitive emissions | F6: Industrial processes and product use | G6: Agriculture | H6: Waste
A7: 2005 | B7: 0 | C7: 0 | D7: 0 | E7: 0 | F7: 0 | G7: 0 | H7: 0
A8: 2006 | B8: 0.031 | C8: -0.001 | D8: 0.027 | E8: 0.059 | F8: 0.05 | G8: -0.036 | H8: -0.003
A9: 2007 | B9: 0.04 | C9: 0.02 | D9: 0.049 | E9: 0.103 | F9: 0.082 | G9: -0.074 | H9: 0.025
A10: 2008 | B10: 0.058 | C10: 0.04 | D10: 0.061 | E10: 0.08 | F10: 0.087 | G10: -0.088 | H10: 0.038
A11: 2009 | B11: 0.059 | C11: 0.001 | D11: 0.072 | E11: 0.067 | F11: 0.012 | G11: -0.104 | H11: 0.027
A12: 2010 | B12: 0.026 | C12: 0.04 | D12: 0.096 | E12: 0.061 | F12: 0.14 | G12: -0.092 | H12: 0.008
A13: 2011 | B13: 0.017 | C13: 0.07 | D13: 0.116 | E13: 0.042 | F13: 0.11 | G13: -0.06 | H13: -0.05
A14: 2012 | B14: -0.024 | C14: 0.107 | D14: 0.125 | E14: 0.06 | F14: 0.013 | G14: -0.048 | H14: -0.104
A15: 2013 | B15: -0.071 | C15: 0.148 | D15: 0.139 | E15: 0.05 | F15: -0.011 | G15: -0.046 | H15: -0.131
A16: 2014 | B16: -0.053 | C16: 0.107 | D16: 0.145 | E16: 0.091 | F16: -0.003 | G16: -0.062 | H16: -0.124
A17: 2015 | B17: -0.024 | C17: 0.105 | D17: 0.167 | E17: 0.179 | F17: 0.017 | G17: -0.089 | H17: -0.093
A18: 2016 | B18: -0.034 | C18: 0.128 | D18: 0.168 | E18: 0.244 | F18: 0.029 | G18: -0.069 | H18: -0.081
... A26: 2024 | B26: -0.229 | C26: 0.213 | D26: 0.24 | E26: 0.136 | F26: 0.021 | G26: -0.078 | H26: -0.129
A27: 2025 | B27: -0.258 | C27: 0.194 | D27: 0.233 | E27: 0.077 | F27: 0.051 | G27: -0.078 | H27: -0.144
A29: Source: Department of Climate Change, Energy, the Environment and Water

Sheet Figure 5
A1: ='Figure 1'!A1 -> Quarterly Update of Australia's National Greenhouse Gas Inventory | Figures and Tables for the December Quarter 2025
A2: Click here to return to contents page
A4: Figure 5: Share of total emissions, by sector, for the year to December 2025
A5: Unit | B5: Electricity | C5: Transport | D5: Stationary energy excluding electricity | E5: Agriculture | F5: Fugitive emissions | G5: Industrial processes and product use | H5: Waste | I5: LULUCF
A6: % | B6: 0.31780826 | C6: 0.21970818 | D6: 0.21136581 | E6: 0.16613064 | F6: 0.099927315 | G6: 0.068986169 | H6: 0.029388676 | I6: -0.11331505
A7: Mt CO2-e | B7: 145.84595 | C7: 100.82666 | D7: 96.998253 | E7: 76.239304 | F7: 45.857819 | G7: 31.658564 | H7: 13.486809 | I7: -52.001607
A9: Source: Department of Climate Change, Energy, the Environment and Water

Sheet Figure 6
A1: ='Figure 1'!A1 -> Quarterly Update of Australia's National Greenhouse Gas Inventory | Figures and Tables for the December Quarter 2025
A2: Click here to return to contents page
A4: Figure 6: Emissions from the electricity sector, by quarter, September 2004 to December 2025
A5: Units: | B5: Million tonnes of carbon dioxide equivalent | C5: Million tonnes of carbon dioxide equivalent
A6: Quarter | B6: Actual emissions | C6: Trend Emissions
A7: 38231 | B7: 51.242025 | C7: 49.026898
A8: 38322 | B8: 46.275027 | C8: 49.067501
A9: 38412 | B9: 49.390666 | C9: 49.239583
A10: 38504 | B10: 49.76577 | C10: 49.587726
A11: 38596 | B11: 52.445799 | C11: 49.950338
A12: 38687 | B12: 47.526414 | C12: 50.214631
A13: 38777 | B13: 50.297628 | C13: 50.419421
A14: 38869 | B14: 50.955975 | C14: 50.642821
A15: 38961 | B15: 53.516209 | C15: 50.863478
A16: 39052 | B16: 47.99107 | C16: 50.94977
A17: 39142 | B17: 50.934334 | C17: 50.962027
A18: 39234 | B18: 51.592353 | C18: 51.087309
... A93: 46082 | B93: 35.354852 | C93: 35.513959
A95: Source: Department of Climate Change, Energy, the Environment and Water

Sheet Figure 7
A1: ='Figure 1'!A1 -> Quarterly Update of Australia's National Greenhouse Gas Inventory | Figures and Tables for the December Quarter 2025
A2: Click here to return to contents page
A4: Figure7: NEM emissions, by quarter, September 2004 to December 2025 (including preliminary March 2026)
A5: Units: | B5: Million tonnes of carbon dioxide equivalent | C5: Million tonnes of carbon dioxide equivalent
A6: Quarter | B6: Actual emissions | C6: Trend emissions
A7: 38231 | B7: 46.289869 | C7: 43.988408
A8: 38322 | B8: 41.339293 | C8: 44.096147
A9: 38412 | B9: 44.285703 | C9: 44.283913
A10: 38504 | B10: 44.776951 | C10: 44.566289
A11: 38596 | B11: 47.424048 | C11: 44.836461
A12: 38687 | B12: 42.520062 | C12: 45.100977
A13: 38777 | B13: 45.194788 | C13: 45.356515
A14: 38869 | B14: 45.917479 | C14: 45.580441
A15: 38961 | B15: 48.290875 | C15: 45.792711
A16: 39052 | B16: 43.071631 | C16: 45.913592
A17: 39142 | B17: 45.954231 | C17: 45.993103
A18: 39234 | B18: 46.661716 | C18: 46.125767
... A92: 45992 | B92: 26.008356 | C92: 29.167139
B93: 28.891941 | C93: 29.037359
A94: Source: Department of Climate Change, Energy, the Environment and Water

Sheet Figure 8
A1: ='Figure 1'!A1 -> Quarterly Update of Australia's National Greenhouse Gas Inventory | Figures and Tables for the December Quarter 2025
A2: Click here to return to contents page
A4: Figure 8: Change in electricity generation in the NEM (trend), by fuel, by quarter, September 2010 to December 2025 (including preliminary March 2026)
A5: Units: TWh | B5: Terawatt hours | C5: Terawatt hours | D5: Terawatt hours | E5: Terawatt hours | F5: Terawatt hours
A6: Year to | B6: Coal | C6: Gas | D6: Wind | E6: Hydro | F6: Large-scale Solar | G6: Small Solar
A7: 40178 | B7: 0 | C7: 0 | D7: 0 | E7: 0 | F7: 0 | G7: 0
A8: 40268 | B8: -0.7977296 | C8: 0.3364221 | D8: 0.013236189 | E8: 0.16932436 | F8: 0 | G8: 0
A9: 40359 | B9: -2.1865192 | C9: 0.73601218 | D9: 0.0505653 | E9: 0.47288031 | F9: 0 | G9: 0
A10: 40451 | B10: -3.4725303 | C10: 0.98737585 | D10: 0.11016278 | E10: 0.83065276 | F10: 0 | G10: 0
A11: 40543 | B11: -3.8574788 | C11: 0.97497467 | D11: 0.16751956 | E11: 0.97090336 | F11: 0 | G11: 0
A12: 40633 | B12: -3.369739 | C12: 0.7133994 | D12: 0.22041436 | E12: 0.74645772 | F12: 0 | G12: 0
A13: 40724 | B13: -2.5891077 | C13: 0.50077161 | D13: 0.26156641 | E13: 0.32376762 | F13: 0 | G13: 0
A14: 40816 | B14: -2.2801629 | C14: 0.43322698 | D14: 0.30222207 | E14: -0.0079615908 | F14: 0 | G14: 0
A15: 40908 | B15: -2.7843928 | C15: 0.4872253 | D15: 0.34081638 | E15: -0.022992287 | F15: 0 | G15: 0
A16: 40999 | B16: -3.7928653 | C16: 0.6629088 | D16: 0.35995554 | E16: 0.292914 | F16: 0 | G16: 0
A17: 41090 | B17: -4.8106723 | C17: 0.86860857 | D17: 0.37016051 | E17: 0.7065913 | F17: 0 | G17: 0
A18: 41182 | B18: -5.5805843 | C18: 1.0949678 | D18: 0.41371662 | E18: 1.0759754 | F18: 0 | G18: 0
... A72: 46112 | B72: -15.284747 | C72: -3.0486149 | D72: 8.8902353 | E72: 0.52387284 | F72: 4.9272853 | G72: 7.7372306
A75: Note: AEMO data on small solar is available from 2016 onwards.
A76: Source: Australian Energy Market Operator (AEMO, 2025), obtained using NEM-Review software

Sheet Figure 9
A1: ='Figure 1'!A1 -> Quarterly Update of Australia's National Greenhouse Gas Inventory | Figures and Tables for the December Quarter 2025
A2: Click here to return to contents page
A4: Figure 9: Stationary energy excluding electricity emissions and energy industries excluding electricity, by quarter, September 2004 to December 2025
A5: Units: | B5: Million tonnes of carbon dioxide equivalent | C5: Million tonnes of carbon dioxide equivalent
A6: Quarter | B6: Stationary energy excluding electricity - Actual | C6: Stationary energy excluding electricity - Trend
A7: 38231 | B7: 22.168495 | C7: 20.101837
A8: 38322 | B8: 19.270844 | C8: 20.258987
A9: 38412 | B9: 18.055878 | C9: 20.421436
A10: 38504 | B10: 21.718664 | C10: 20.378647
A11: 38596 | B11: 22.189019 | C11: 20.187612
A12: 38687 | B12: 19.126895 | C12: 20.08519
A13: 38777 | B13: 17.822088 | C13: 20.143587
A14: 38869 | B14: 21.363412 | C14: 20.22977
A15: 38961 | B15: 22.492768 | C15: 20.256196
A16: 39052 | B16: 19.490304 | C16: 20.284859
A17: 39142 | B17: 17.772764 | C17: 20.416637
A18: 39234 | B18: 21.661578 | C18: 20.619207
... A92: 45992 | B92: 23.874851 | C92: 24.393912
A95: Source: Department of Climate Change, Energy, the Environment and Water

Sheet Figure 10
A1: ='Figure 1'!A1 -> Quarterly Update of Australia's National Greenhouse Gas Inventory | Figures and Tables for the December Quarter 2025
A2: Click here to return to contents page
A4: Figure 10: LNG exports, by quarter, September 2004 to December 2025
A5: Units: | B5: Millions tonnes
A6: Year | B6: LNG
A7: 38231 | B7: 2.4577346
A8: 38322 | B8: 2.8311526
A9: 38412 | B9: 2.65
A10: 38504 | B10: 2.65
A11: 38596 | B11: 2.844
A12: 38687 | B12: 2.868
A13: 38777 | B13: 3.0033684
A14: 38869 | B14: 3.3138596
A15: 38961 | B15: 3.5091579
A16: 39052 | B16: 3.7938596
A17: 39142 | B17: 3.3155088
A18: 39234 | B18: 3.7137544
... A92: 45992 | B92: 20.124291
A94: Source: Department of Climate Change, Energy, the Environment and Water

Sheet Figure 11
A1: ='Figure 1'!A1 -> Quarterly Update of Australia's National Greenhouse Gas Inventory | Figures and Tables for the December Quarter 2025
A2: Click here to return to contents page
A4: Figure 11: Transport emissions, actual and trend, by quarter, September 2004 to December 2025
A5: Units: | B5: Million tonnes of carbon dioxide equivalent | C5: Million tonnes of carbon dioxide equivalent
A6: Quarter | B6: Transport - Actual | C6: Transport - Trend
A7: 38231 | B7: 20.321232 | C7: 20.340429
A8: 38322 | B8: 21.188092 | C8: 20.409256
A9: 38412 | B9: 19.80219 | C9: 20.490166
A10: 38504 | B10: 20.492376 | C10: 20.567086
A11: 38596 | B11: 20.631415 | C11: 20.638635
A12: 38687 | B12: 21.490895 | C12: 20.709536
A13: 38777 | B13: 20.098388 | C13: 20.803398
A14: 38869 | B14: 20.833641 | C14: 20.925697
A15: 38961 | B15: 21.0809 | C15: 21.057175
A16: 39052 | B16: 21.959716 | C16: 21.173255
A17: 39142 | B17: 20.543739 | C17: 21.278801
A18: 39234 | B18: 21.329405 | C18: 21.392428
... A92: 45992 | B92: 26.276151 | C92: 25.364215
A95: Source: Department of Climate Change, Energy, the Environment and Water

Sheet Figure 12
A1: ='Figure 1'!A1 -> Quarterly Update of Australia's National Greenhouse Gas Inventory | Figures and Tables for the December Quarter 2025
A2: Click here to return to contents page
A4: Figure 12: Consumption of primary liquid fuels, actual and trend, by quarter, June 2005 to December 2025
A5: Units: | B5: Million Litres fuel sold | C5: Million Litres fuel sold | D5: Million Litres fuel sold | E5: Million Litres fuel sold
A6: Quarter | B6: Petrol | C6: Diesel | D6: Petrol - Trend | E6: Diesel - Trend
A7: 38504 | B7: 4846.73 | C7: 3967.683 | D7: 4791.3756 | E7: 3924.7197
A8: 38596 | B8: 4658.9303 | C8: 3756.317 | D8: 4783.9923 | E8: 3925.1422
A9: 38687 | B9: 4894.5536 | C9: 4126.419 | D9: 4768.1922 | E9: 3933.2387
A10: 38777 | B10: 4735.1393 | C10: 3750.888 | D10: 4750.0855 | E10: 3941.1374
A11: 38869 | B11: 4594.2518 | C11: 3967.683 | D11: 4742.5014 | E11: 3956.437
A12: 38961 | B12: 4787.6023 | C12: 3992.026 | D12: 4752.9189 | E12: 4008.7057
A13: 39052 | B13: 4916.5012 | C13: 4277.196 | D13: 4788.1923 | E13: 4089.7379
A14: 39142 | B14: 4799.5388 | C14: 4007.27 | D14: 4833.7396 | E14: 4159.3641
A15: 39234 | B15: 4733.6357 | C15: 4187.859 | D15: 4860.5489 | E15: 4201.9012
A16: 39326 | B16: 4899.5047 | C16: 4278.787 | D16: 4855.3674 | E16: 4253.1366
A17: 39417 | B17: 4948.8567 | C17: 4523.241 | D17: 4824.3056 | E17: 4357.8427
A18: 39508 | B18: 4741.2381 | C18: 4244.058 | D18: 4773.7751 | E18: 4492.2675
... A89: 45992 | B89: 4108.2 | C89: 8783.3 | D89: 3962.695 | E89: 8502.2836
A92: Source: Department of Climate Change, Energy, the Environment and Water

Sheet Figure 13
A1: ='Figure 1'!A1 -> Quarterly Update of Australia's National Greenhouse Gas Inventory | Figures and Tables for the December Quarter 2025
A2: Click here to return to contents page
A4: Figure 13: Fugitive emissions, actual and trend, by sub-sector, by quarter September 2004 to December 2025
A5: Units: | B5: Million tonnes of carbon dioxide equivalent | C5: Million tonnes of carbon dioxide equivalent | D5: Million tonnes of carbon dioxide equivalent | E5: Million tonnes of carbon dioxide equivalent
A6: Quarter | B6: Coal - actual emissions | C6: Oil and natural gas - actual emissions | D6: Coal - trend | E6: Oil and natural gas - trend
A7: 38231 | B7: 7.7746145 | C7: 3.1063397 | D7: 7.6467428 | E7: 2.8475895
A8: 38322 | B8: 7.7086515 | C8: 2.7874004 | D8: 7.7176996 | E8: 2.8698126
A9: 38412 | B9: 7.7576049 | C9: 2.6577627 | D9: 7.81441 | E9: 2.8939189
A10: 38504 | B10: 7.8378646 | C10: 2.9601269 | D10: 7.8799727 | E10: 2.8953909
A11: 38596 | B11: 8.0984305 | C11: 3.1359152 | D11: 7.9167632 | E11: 2.8866381
A12: 38687 | B12: 8.0081999 | C12: 2.8122251 | D12: 7.9417899 | E12: 2.8931296
A13: 38777 | B13: 7.7917459 | C13: 2.6906688 | D13: 8.0128912 | E13: 2.9209812
A14: 38869 | B14: 8.0621468 | C14: 2.9774447 | D14: 8.1547236 | E14: 2.9541002
A15: 38961 | B15: 8.6490488 | C15: 3.2782062 | D15: 8.4028345 | E15: 2.9794213
A16: 39052 | B16: 8.7155049 | C16: 2.9380048 | D16: 8.6681888 | E16: 3.0065003
A17: 39142 | B17: 8.5600644 | C17: 2.7662172 | D17: 8.8347762 | E17: 3.0396026
A18: 39234 | B18: 8.8929435 | C18: 3.1054814 | D18: 8.8134144 | E18: 3.0667061
... A92: 45992 | B92: 6.4554702 | C92: 5.3948439 | D92: 6.3042437 | E92: 5.3692855
A95: Source: Department of Climate Change, Energy, the Environment and Water

Sheet Figure 14
A1: ='Figure 1'!A1 -> Quarterly Update of Australia's National Greenhouse Gas Inventory | Figures and Tables for the December Quarter 2025
A2: Click here to return to contents page
A4: Figure 14: Industrial processes and product use emissions, actual, by sub-sector, by quarter, September 2004 to December 2025
A5: Units: | B5: Million tonnes of carbon dioxide equivalent | C5: Million tonnes of carbon dioxide equivalent | D5: Million tonnes of carbon dioxide equivalent | E5: Million tonnes of carbon dioxide equivalent | F5: Million tonnes of carbon dioxide equivalent
A6: Quarter | B6: Chemical industry | C6: Products substituted for Ozone Depleting Substances | D6: Metal industry | E6: Mineral industry | F6: Other product and lubricant use
A7: 38231 | B7: 1.2720943 | C7: 0.93248028 | D7: 3.4683644 | E7: 1.6330018 | F7: 0.10762286
A8: 38322 | B8: 1.2720943 | C8: 0.93248028 | D8: 3.5020776 | E8: 1.6330018 | F8: 0.10762286
A9: 38412 | B9: 1.2444401 | C9: 0.91220897 | D9: 3.5869629 | E9: 1.5975017 | F9: 0.10528323
A10: 38504 | B10: 1.2582672 | C10: 0.92234463 | D10: 3.663432 | E10: 1.6152517 | F10: 0.10645304
A11: 38596 | B11: 1.4439194 | C11: 1.0356212 | D11: 3.4522437 | E11: 1.6809529 | F11: 0.1032325
A12: 38687 | B12: 1.4439194 | C12: 1.0356212 | D12: 3.3239275 | E12: 1.6809529 | F12: 0.1032325
A13: 38777 | B13: 1.4125299 | C13: 1.0131077 | D13: 3.2835095 | E13: 1.6444104 | F13: 0.10098831
A14: 38869 | B14: 1.4282247 | C14: 1.0243645 | D14: 3.3923636 | E14: 1.6626816 | F14: 0.1021104
A15: 38961 | B15: 1.6144909 | C15: 1.1862648 | D15: 3.5135256 | E15: 1.7607222 | F15: 0.097241139
A16: 39052 | B16: 1.6144909 | C16: 1.1862648 | D16: 3.4979842 | E16: 1.7607222 | F16: 0.097241139
A17: 39142 | B17: 1.5793933 | C17: 1.1604764 | D17: 3.4485734 | E17: 1.7224456 | F17: 0.095127201
A18: 39234 | B18: 1.5969421 | C18: 1.1733706 | D18: 3.4845721 | E18: 1.7415839 | F18: 0.09618417
... A92: 45992 | B92: 1.0610746 | C92: 2.7932278 | D92: 2.690832 | E92: 1.2783416 | F92: 0.076789604
A95: Source: Department of Climate Change, Energy, the Environment and Water

Sheet Figure 15
A1: ='Figure 1'!A1 -> Quarterly Update of Australia's National Greenhouse Gas Inventory | Figures and Tables for the December Quarter 2025
A2: Click here to return to contents page
A4: Figure 15: Agriculture emissions, actual and trend, by quarter, September 2004 to December 2025
A5: Units: | B5: Million tonnes of carbon dioxide equivalent | C5: Million tonnes of carbon dioxide equivalent
A6: Quarter | B6: Agriculture emissions (actual) | C6: Agriculture emissions (trend)
A7: 38231 | B7: 20.852907 | C7: 20.780986
A8: 38322 | B8: 20.852907 | C8: 20.720417
A9: 38412 | B9: 20.399583 | C9: 20.635793
A10: 38504 | B10: 20.626245 | C10: 20.554337
A11: 38596 | B11: 20.531213 | C11: 20.502689
A12: 38687 | B12: 20.531213 | C12: 20.441771
A13: 38777 | B13: 20.084883 | C13: 20.294167
A14: 38869 | B14: 20.308048 | C14: 20.05987
A15: 38961 | B15: 19.674798 | C15: 19.791931
A16: 39052 | B16: 19.674798 | C16: 19.584186
A17: 39142 | B17: 19.247085 | C17: 19.429434
A18: 39234 | B18: 19.460941 | C18: 19.247471
... A92: 45992 | B92: 19.091937 | C92: 18.926983
A95: Source: Department of Climate Change, Energy, the Environment and Water

Sheet Figure 16
A1: ='Figure 1'!A1 -> Quarterly Update of Australia's National Greenhouse Gas Inventory | Figures and Tables for the December Quarter 2025
A2: Click here to return to contents page
A4: Figure 16: Waste emissions, actual, by sub-sector, by quarter, September 2004 to December 2025
A5: Units: | B5: Million tonnes of carbon dioxide equivalent | C5: Million tonnes of carbon dioxide equivalent | D5: Million tonnes of carbon dioxide equivalent
A6: Quarter | B6: Solid waste disposal on land | C6: Wastewater handling | D6: Incineration and biological treatment of solid waste
A7: 40238 | B7: 2.8382288 | C7: 0.85472939 | D7: 0.060299139
A8: 38231 | B8: 3.0970939 | C8: 0.83115019 | D8: 0.04387858
A9: 38322 | B9: 3.0970939 | C9: 0.83115019 | D9: 0.04387858
A10: 38412 | B10: 3.0297658 | C10: 0.8130817 | D10: 0.042924698
A11: 38504 | B11: 3.0634298 | C11: 0.82211594 | D11: 0.043401639
A12: 38596 | B12: 3.0226032 | C12: 0.84019545 | D12: 0.04676029
A13: 38687 | B13: 3.0226032 | C13: 0.84019545 | D13: 0.04676029
A14: 38777 | B14: 2.9568944 | C14: 0.82193033 | D14: 0.045743762
A15: 38869 | B15: 2.9897488 | C15: 0.83106289 | D15: 0.046252026
A16: 38961 | B16: 3.107341 | C16: 0.85323794 | D16: 0.049048882
A17: 39052 | B17: 3.107341 | C17: 0.85323794 | D17: 0.049048882
A18: 39142 | B18: 3.0397901 | C18: 0.83468929 | D18: 0.047982602
... A93: 45992 | B93: 2.5286232 | C93: 0.78673669 | D93: 0.084054933
A96: Source: Department of Climate Change, Energy, the Environment and Water

Sheet Figure 17
A1: ='Figure 1'!A1 -> Quarterly Update of Australia's National Greenhouse Gas Inventory | Figures and Tables for the December Quarter 2025
A2: Click here to return to contents page
A4: Figure 17: LULUCF net anthropogenic emissions, by sub-sector, from year to December 2025
A5: Units: | B5: Million tonnes of carbon dioxide equivalent | C5: Million tonnes of carbon dioxide equivalent | D5: Million tonnes of carbon dioxide equivalent | E5: Million tonnes of carbon dioxide equivalent | F5: Million tonnes of carbon dioxide equivalent | G5: Million tonnes of carbon dioxide equivalent
A6: Quarter Period | B6: Forest land converted to other uses (Cropland, Grassland, Settlements, and Wetland) | C6: Cropland remaining cropland | D6: Land Remaining Land (Grassland, Settlements, and Wetland) | E6: Land converted to forest | F6: Forest remaining forest | G6: Harvested Wood Products
A7: 38687 | B7: 100.54722 | C7: 5.7663839 | D7: 28.626787 | E7: -21.301492 | F7: -13.303337 | G7: -7.7153514
A8: 39052 | B8: 96.833743 | C8: 5.7161629 | D8: 31.970513 | E8: -22.922744 | F8: -9.2045054 | G8: -6.9787532
A9: 39417 | B9: 79.955476 | C9: 4.637609 | D9: 21.140896 | E9: -21.88561 | F9: -1.290507 | G9: -6.3996115
A10: 39783 | B10: 64.275132 | C10: 3.7254847 | D10: 16.952697 | E10: -23.386925 | F10: 9.8840756 | G10: -5.4699698
A11: 40148 | B11: 58.169773 | C11: 3.3358783 | D11: 17.952075 | E11: -25.619948 | F11: 15.818868 | G11: -4.3431707
A12: 40513 | B12: 53.690761 | C12: 2.9972488 | D12: 14.369946 | E12: -35.754742 | F12: 21.011728 | G12: -4.3310216
A13: 40878 | B13: 39.281754 | C13: 1.6691532 | D13: 7.8292035 | E13: -38.529927 | F13: 16.028054 | G13: -4.2224043
A14: 41244 | B14: 45.673374 | C14: -1.6548105 | D14: 2.8940446 | E14: -31.022854 | F14: 1.8927565 | G14: -3.9302299
A15: 41609 | B15: 57.034254 | C15: -4.1425496 | D15: 4.3868626 | E15: -32.582755 | F15: -7.2732375 | G15: -3.8358725
A16: 41974 | B16: 50.957413 | C16: -4.3897431 | D16: 6.3526818 | E16: -34.239896 | F16: -13.283987 | G16: -3.857279
A17: 42339 | B17: 37.11786 | C17: -4.5100998 | D17: 4.3988312 | E17: -38.130046 | F17: -25.554419 | G17: -4.0822553
A18: 42705 | B18: 41.002641 | C18: -4.4386443 | D18: 5.3743305 | E18: -43.834111 | F18: -34.951074 | G18: -4.1684896
... A27: 45992 | B27: 21.572592 | C27: -7.4261856 | D27: -0.55766273 | E27: -39.826541 | F27: -20.505911 | G27: -5.2578991
A30: Source: Department of Climate Change, Energy, the Environment and Water

Sheet Figure 18
A1: ='Figure 1'!A1 -> Quarterly Update of Australia's National Greenhouse Gas Inventory | Figures and Tables for the December Quarter 2025
A2: Click here to return to contents page
A4: Figure 18: Emissions per capita and per dollar of real GDP, by quarter, September 2004 to December 2025
A5: Units: | B5: tonnes of carbon dioxide equivalent per person | C5: kilograms of carbon dioxide equivalent per dollar of real GDP
A6: Quarter | B6: Emissions per capita (trend) | C6: Emissions per dollar of real GDP - trend (RHS)
A7: 38231 | B7: 7.5841356 | C7: 0.37146057
A8: 38322 | B8: 7.577285 | C8: 0.3699974
A9: 38412 | B9: 7.6081756 | C9: 0.36970475
A10: 38504 | B10: 7.6997608 | C10: 0.3720672
A11: 38596 | B11: 7.8216866 | C11: 0.37640805
A12: 38687 | B12: 7.9068264 | C12: 0.379738
A13: 38777 | B13: 7.9042092 | C13: 0.3793066
A14: 38869 | B14: 7.8181454 | C14: 0.37442548
A15: 38961 | B15: 7.7025567 | C15: 0.36681339
A16: 39052 | B16: 7.6079315 | C16: 0.35935822
A17: 39142 | B17: 7.5433319 | C17: 0.35378237
A18: 39234 | B18: 7.4855883 | C18: 0.34918951
... A92: 45992 | B92: 4.143172 | C92: 0.16687423
A94: Sources:
A95: Australian Bureau of Statistics (2025), Australian Demographic Statistics, pub. no. 3101 http://www.abs.gov.au/ausstats/abs@.nsf/mf/3101.0
A96: Australian Bureau of Statistics (2025), Population Clock. http://www.abs.gov.au/AUSSTATS/abs@.nsf/Web+Pages/Population+Clock
A97: Australian Bureau of Statistics (2025), National Accounts: National Income, Expenditure and Product, Cat. No. 5206.0
A98: http://www.abs.gov.au/ausstats/abs@.nsf/mf/5206.0

Sheet Figure ST1
A1: ='Figure 1'!A1 -> Quarterly Update of Australia's National Greenhouse Gas Inventory | Figures and Tables for the December Quarter 2025
A2: Click here to return to contents page
A4: Figure ST1: Total cleared area, Australia, 1989-90 to 2023-24
B6: Primary Forest Conversion | C6: Secondary Forest Reclearing | D6: Total area cleared
A7: 1989-90 | B7: 597.53584 | C7: 322.71233 | D7: =SUM(B7:C7) -> 920.24817
A8: 1990-91 | B8: 481.84691 | C8: 353.28285 | D8: =SUM(B8:C8) -> 835.12975
A9: 1991-92 | B9: 379.4917 | C9: 393.13091 | D9: =SUM(B9:C9) -> 772.62261
A10: 1992-93 | B10: 269.50596 | C10: 313.65371 | D10: =SUM(B10:C10) -> 583.15967
A11: 1993-94 | B11: 274.46718 | C11: 337.25952 | D11: =SUM(B11:C11) -> 611.72669
A12: 1994-95 | B12: 219.64996 | C12: 259.63663 | D12: =SUM(B12:C12) -> 479.28659
A13: 1995-96 | B13: 224.7627 | C13: 294.1582 | D13: =SUM(B13:C13) -> 518.9209
A14: 1996-97 | B14: 223.26333 | C14: 286.10692 | D14: =SUM(B14:C14) -> 509.37026
A15: 1997-98 | B15: 226.1475 | C15: 302.84944 | D15: =SUM(B15:C15) -> 528.99694
A16: 1998-99 | B16: 263.38996 | C16: 379.86755 | D16: =SUM(B16:C16) -> 643.25751
A17: 1999-00 | B17: 271.26218 | C17: 347.30504 | D17: =SUM(B17:C17) -> 618.56722
A18: 2000-01 | B18: 315.17 | C18: 400.87881 | D18: =SUM(B18:C18) -> 716.04881
... A41: 2023-24 | B41: 21.587403 | C41: 164.57221 | D41: =SUM(B41:C41) -> 186.15961

Sheet Figure ST2
A1: ='Figure 1'!A1 -> Quarterly Update of Australia's National Greenhouse Gas Inventory | Figures and Tables for the December Quarter 2025
A2: Click here to return to contents page
A4: Figure ST2: Disaggregated emissions associated with forest conversions
B6: A: Direct emissions from primary clearing | C6: B: Direct emissions from reclearing | D6: C: All other emissions on lands with a history of clearing
A7: 1989-90 | B7: 118.20053 | C7: 9.741403 | D7: 45.133507
A8: 1990-91 | B8: 104.66403 | C8: 9.7644109 | D8: 39.124668
A9: 1991-92 | B9: 71.826512 | C9: 9.2333789 | D9: 38.151818
A10: 1992-93 | B10: 57.749781 | C10: 8.3588929 | D10: 37.014451
A11: 1993-94 | B11: 48.691541 | C11: 8.5303559 | D11: 26.60472
A12: 1994-95 | B12: 44.238582 | C12: 8.3038515 | D12: 22.466349
A13: 1995-96 | B13: 36.585302 | C13: 7.0585657 | D13: 22.779311
A14: 1996-97 | B14: 39.405358 | C14: 8.7731014 | D14: 23.350929
A15: 1997-98 | B15: 37.030548 | C15: 9.3287973 | D15: 19.421019
A16: 1998-99 | B16: 42.081977 | C16: 11.245123 | D16: 26.291657
A17: 1999-00 | B17: 43.38164 | C17: 12.908861 | D17: 18.321396
A18: 2000-01 | B18: 45.131586 | C18: 13.414819 | D18: 32.258798
... A39: 2021-22 | B39: 5.8591248 | C39: 8.5932349 | D39: -8.5786488
A40: 2022-23 | B40: 5.8591248 | C40: 8.5932349 | D40: =25301/1000 -> 25.301
A41: 2023-24 | B41: 5.8591248 | C41: 8.5932349 | D41: =12852/1000 -> 12.852

Sheet Figure ST3
A1: ='Figure 1'!A1 -> Quarterly Update of Australia's National Greenhouse Gas Inventory | Figures and Tables for the December Quarter 2025
A2: Click here to return to contents page
A4: Figure ST3: Net emissions from regrowth and regenerating forest
B6: Emissions | D6: Cumulative Area
B7: Actual | C7: Trend
B8: Net emissions from regrowth and regenerating forest (actual) | C8: Net emissions from regrowth and regenerating forest (trend) | D8: Cumulative area of regrowth and regenerating forest
A9: 1989-90 | B9: -3.5712665 | C9: -4.1552106 | D9: 3010.3634
A10: 1990-91 | B10: -4.005905 | C10: -4.4699592 | D10: 3596.2329
A11: 1991-92 | B11: -4.8884602 | C11: -4.3812609 | D11: 4061.2711
A12: 1992-93 | B12: -5.4142051 | C12: -5.263838 | D12: 4429.0551
A13: 1993-94 | B13: -4.0264677 | C13: -5.909773 | D13: 4747.2441
A14: 1994-95 | B14: -7.984152 | C14: -7.0175198 | D14: 5084.6557
A15: 1995-96 | B15: -7.2355799 | C15: -7.9791269 | D15: 5337.853
A16: 1996-97 | B16: -10.427194 | C16: -9.7225798 | D16: 5595.7281
A17: 1997-98 | B17: -10.222241 | C17: -11.089959 | D17: 5828.7228
A18: 1998-99 | B18: -12.743732 | C18: -11.212152 | D18: 6050.5992
A19: 1999-00 | B19: -14.82105 | C19: -10.618012 | D19: 6300.5337
A20: 2000-01 | B20: -7.8465438 | C20: -9.9836314 | D20: 6453.4794
... A43: 2023-24 | B43: -28.097476 | C43: -32.542113 | D43: 13813.612

Sheet Figure ST4
A1: ='Figure 1'!A1 -> Quarterly Update of Australia's National Greenhouse Gas Inventory | Figures and Tables for the December Quarter 2025
A2: Click here to return to contents page
A4: Figure ST4: Harvest Area and Net Emissions in Harvested Native Forests
B6: Area Harvested (ha) | C6: Net Emissions (Mt CO2-e) | D6: Emissions Trend (Mt CO2-e)
A7: 1989-90 | B7: 166858.45 | C7: -5.7099122 | D7: =AVERAGE(C7:C11) -> -9.5376999
A8: 1990-91 | B8: 146612.1 | C8: -7.3231027 | D8: =AVERAGE(C7:C12) -> -8.6603272
A9: 1991-92 | B9: 189219.64 | C9: -14.146867 | D9: =AVERAGE(C7:C13) -> -8.9300875
A10: 1992-93 | B10: 188900.63 | C10: -16.329292 | D10: =AVERAGE(C7:C14) -> -9.7396061
A11: 1993-94 | B11: 180305.59 | C11: -4.1793267 | D11: =AVERAGE(C7:C15) -> -9.2208246
A12: 1994-95 | B12: 179159.96 | C12: -4.2734633 | D12: =AVERAGE(C8:C16) -> -10.008898
A13: 1995-96 | B13: 166306.58 | C13: -10.54865 | D13: =AVERAGE(C9:C17) -> -9.7017184
A14: 1996-97 | B14: 134842.24 | C14: -15.406236 | D14: =AVERAGE(C10:C18) -> -9.0828706
A15: 1997-98 | B15: 142707.37 | C15: -5.0705732 | D15: =AVERAGE(C11:C19) -> -9.0761603
A16: 1998-99 | B16: 116485.75 | C16: -12.802573 | D16: =AVERAGE(C12:C20) -> -10.834037
A17: 1999-00 | B17: 103576.1 | C17: -4.5584863 | D17: =AVERAGE(C13:C21) -> -12.960349
A18: 2000-01 | B18: 123697.88 | C18: -8.5772362 | D18: =AVERAGE(C14:C22) -> -14.242493
A19: 2001-02 | B19: 106103.36 | C19: -16.268899 | D19: =AVERAGE(C15:C23) -> -15.064149
A20: 2002-03 | B20: 93705.512 | C20: -20.000216 | D20: =AVERAGE(C16:C24) -> -16.951623
A21: 2003-04 | B21: 108925.91 | C21: -23.410275 | D21: =AVERAGE(C17:C25) -> -17.912815
A22: 2004-05 | B22: 111693.94 | C22: -22.087939 | D22: =AVERAGE(C18:C26) -> -18.419496
... A37: 2019-20 | B37: 42915.765 | C37: -33.954415 | D37: =AVERAGE(C33:C41) -> -35.627981
A38: 2020-21 | B38: 33376.877 | C38: -34.122776 | D38: =AVERAGE(C34:C41) -> -35.282274
A39: 2021-22 | B39: 38538.638 | C39: -28.031542 | D39: =AVERAGE(C35:C41) -> -34.390408
A40: 2022-23 | B40: 31756.899 | C40: -28.465062 | D40: =AVERAGE(C36:C41) -> -32.269228
A41: 2023-24 | B41: 27843.756 | C41: -30.777373 | D41: =AVERAGE(C37:C41) -> -31.070233

Sheet Figure ST5
A1: ='Figure 1'!A1 -> Quarterly Update of Australia's National Greenhouse Gas Inventory | Figures and Tables for the December Quarter 2025
A2: Click here to return to contents page
A4: Figure ST5: Net emissions from savanna fire management in ACCU project areas and non-project areas
B7: Non-Project Areas | E7: Project Areas
A8: Year | B8: Annual Emissions | C8: Average, 1993-2012 | D8: Average, 2013-2024 | E8: Annual Emissions | F8: Average, 1993-2012 | G8: Average, 2013-2024
A9: 1988 | B9: -3117.6153 | E9: -6583.9714
A10: 1989 | B10: 9592.3034 | E10: 10378.756
A11: 1990 | B11: 8008.0999 | E11: 33150.625
A12: 1991 | B12: 9497.7558 | E12: 21028.744
A13: 1992 | B13: 4789.8816 | E13: 24566.483
A14: 1993 | B14: -3769.944 | C14: 13048.887 | E14: 6806.7859 | F14: 12766.159
A15: 1994 | B15: -4873.9308 | C15: 13048.887 | E15: 4242.8028 | F15: 12766.159
A16: 1995 | B16: 30199.39 | C16: 13048.887 | E16: 22361.411 | F16: 12766.159
A17: 1996 | B17: 18282.365 | C17: 13048.887 | E17: 3377.2938 | F17: 12766.159
A18: 1997 | B18: 18531.417 | C18: 13048.887 | E18: 27178.58 | F18: 12766.159
A19: 1998 | B19: 32654.297 | C19: 13048.887 | E19: 27307.529 | F19: 12766.159
A20: 1999 | B20: 3430.141 | C20: 13048.887 | E20: -4488.057 | F20: 12766.159
A21: 2000 | B21: 21114.01 | C21: 13048.887 | E21: 23835.583 | F21: 12766.159
A22: 2001 | B22: 12791.95 | C22: 13048.887 | E22: 7560.0135 | F22: 12766.159
A23: 2002 | B23: 35890.384 | C23: 13048.887 | E23: 28903.149 | F23: 12766.159
A24: 2003 | B24: -10154.415 | C24: 13048.887 | E24: 2917.6837 | F24: 12766.159
A25: 2004 | B25: 6298.5665 | C25: 13048.887 | E25: 17337.933 | F25: 12766.159
... A33: 2012 | B33: 27968.413 | C33: 13048.887 | E33: 17168.057 | F33: 12766.159
A34: 2013 | B34: 46151.542 | D34: 10661.646 | E34: 13478.145 | G34: 130.96366
A35: 2014 | B35: -13139.481 | D35: 10661.646 | E35: -7289.1912 | G35: 130.96366
A36: 2015 | B36: 22885.06 | D36: 10661.646 | E36: 24798.517 | G36: 130.96366
A37: 2016 | B37: -3218.8814 | D37: 10661.646 | E37: -11794.166 | G37: 130.96366
A38: 2017 | B38: 13050.372 | D38: 10661.646 | E38: 2096.8847 | G38: 130.96366
A39: 2018 | B39: 1384.2734 | D39: 10661.646 | E39: -10904.078 | G39: 130.96366
A40: 2019 | B40: -1578.2465 | D40: 10661.646 | E40: -11897.414 | G40: 130.96366
A41: 2020 | B41: 628.55022 | D41: 10661.646 | E41: 4387.2303 | G41: 130.96366
A42: 2021 | B42: -6347.7397 | D42: 10661.646 | E42: -4678.1802 | G42: 130.96366
A43: 2022 | B43: 7483.4625 | D43: 10661.646 | E43: -6707.8583 | G43: 130.96366
A44: 2023 | B44: 9210.659 | D44: 10661.646 | E44: -2751.028 | G44: 130.96366
A45: 2024 | B45: 51430.179 | D45: 10661.646 | E45: 12832.702 | G45: 130.96366

Sheet Data Table 1A
A1: ='Figure 1'!A1 -> Quarterly Update of Australia's National Greenhouse Gas Inventory | Figures and Tables for the December Quarter 2025
A2: Click here to return to contents page
A4: Data Table 1A: Actual emissions (Mt), by sector, by quarter, since 2004-05 (including preliminary March 2026)
A5: Year | B5: Quarter | C5: Energy | G5: Industrial Processes and Product Use | H5: Agriculture | I5: Waste | J5: Land Use, Land Use Change and Forestry (LULUCF) | K5: National Inventory Total
C6: Electricity | D6: Stationary Energy excl. electricity | E6: Transport | F6: Fugitive Emissions
A7: 2004-05 | B7: 38231 | C7: 51.242025 | D7: 22.168495 | E7: 20.321232 | F7: 10.880954 | G7: 7.4771329 | H7: 20.852907 | I7: 3.9721227 | J7: 19.365831 | K7: 156.2807
B8: 38322 | C8: 46.275027 | D8: 19.270844 | E8: 21.188092 | F8: 10.496052 | G8: 7.5108461 | H8: 20.852907 | I8: 3.9721227 | J8: 19.365831 | K8: 148.93172
B9: 38412 | C9: 49.390666 | D9: 18.055878 | E9: 19.80219 | F9: 10.415368 | G9: 7.5085842 | H9: 20.399583 | I9: 3.8857722 | J9: 18.944835 | K9: 148.40287
B10: 38504 | C10: 49.76577 | D10: 21.718664 | E10: 20.492376 | F10: 10.797992 | G10: 7.6286269 | H10: 20.626245 | I10: 3.9289474 | J10: 19.155333 | K10: 154.11395
A11: 2005-06 | B11: 38596 | C11: 52.445799 | D11: 22.189019 | E11: 20.631415 | F11: 11.234346 | G11: 7.777094 | H11: 20.531213 | I11: 3.9095589 | J11: 27.260022 | K11: 165.97847
B12: 38687 | C12: 47.526414 | D12: 19.126895 | E12: 21.490895 | F12: 10.820425 | G12: 7.6487778 | H12: 20.531213 | I12: 3.9095589 | J12: 27.260022 | K12: 158.3142
B13: 38777 | C13: 50.297628 | D13: 17.822088 | E13: 20.098388 | F13: 10.482415 | G13: 7.5143413 | H13: 20.084883 | I13: 3.8245685 | J13: 26.667413 | K13: 156.79172
B14: 38869 | C14: 50.955975 | D14: 21.363412 | E14: 20.833641 | F14: 11.039591 | G14: 7.6702046 | H14: 20.308048 | I14: 3.8670637 | J14: 26.963717 | K14: 163.00165
A15: 2006-07 | B15: 38961 | C15: 53.516209 | D15: 22.492768 | E15: 21.0809 | F15: 11.927255 | G15: 8.2291775 | H15: 19.674798 | I15: 4.0096278 | J15: 20.891643 | K15: 161.82238
B16: 39052 | C16: 47.99107 | D16: 19.490304 | E16: 21.959716 | F16: 11.65351 | G16: 8.2136361 | H16: 19.674798 | I16: 4.0096278 | J16: 20.891643 | K16: 153.8843
B17: 39142 | C17: 50.934334 | D17: 17.772764 | E17: 20.543739 | F17: 11.326282 | G17: 8.0617111 | H17: 19.247085 | I17: 3.922462 | J17: 20.437477 | K17: 152.24585
B18: 39234 | C18: 51.592353 | D18: 21.661578 | E18: 21.329405 | F18: 11.998425 | G18: 8.1489669 | H18: 19.460941 | I18: 3.9660449 | J18: 20.66456 | K18: 158.82227
A19: 2007-08 | B19: 39326 | C19: 53.730104 | D19: 23.290352 | E19: 21.531245 | F19: 12.254246 | G19: 8.2265138 | H19: 18.949299 | I19: 4.1300678 | J19: 17.528107 | K19: 159.63993
B20: 39417 | C20: 48.311551 | D20: 20.108882 | E20: 22.413682 | F20: 11.406277 | G20: 8.1689034 | H20: 18.949299 | I20: 4.1300678 | J20: 17.528107 | K20: 151.01677
B21: 39508 | C21: 51.69329 | D21: 18.043219 | E21: 20.983448 | F21: 10.57237 | G21: 8.1039057 | H21: 18.743329 | I21: 4.0851758 | J21: 17.337584 | K21: 149.56232
B22: 39600 | C22: 52.137519 | D22: 22.362335 | E22: 21.829503 | F22: 11.94591 | G22: 8.1683492 | H22: 18.743329 | I22: 4.0851758 | J22: 17.337584 | K22: 156.60971
A23: 2008-09 | B23: 39692 | C23: 54.995352 | D23: 23.719932 | E23: 21.547032 | F23: 11.867949 | G23: 8.4346447 | H23: 18.99531 | I23: 4.0975979 | J23: 15.652663 | K23: 159.31048
B24: 39783 | C24: 49.255498 | D24: 20.298289 | E24: 22.456945 | F24: 11.60154 | G24: 8.0530253 | H24: 18.99531 | I24: 4.0975979 | J24: 15.652663 | K24: 150.41087
B25: 39873 | C25: 53.506099 | D25: 17.264348 | E25: 21.038195 | F25: 10.757747 | G25: 6.945787 | H25: 18.582368 | I25: 4.0085197 | J25: 15.312387 | K25: 147.41545
B26: 39965 | C26: 53.643344 | D26: 21.417432 | E26: 21.900181 | F26: 11.666678 | G26: 7.019859 | H26: 18.788839 | I26: 4.0530588 | J26: 15.482525 | K26: 153.97192
A27: 2009-10 | B27: 40057 | C27: 53.244302 | D27: 22.737937 | E27: 21.892869 | F27: 11.571269 | G27: 8.1178972 | H27: 18.36236 | I27: 4.0604292 | J27: 17.259282 | K27: 157.24634
B28: 40148 | C28: 47.876542 | D28: 19.890681 | E28: 22.833747 | F28: 11.452366 | G28: 8.411521 | H28: 18.36236 | I28: 4.0604292 | J28: 17.259282 | K28: 150.14693
B29: 40238 | C29: 51.85236 | D29: 18.165504 | E29: 21.399929 | F29: 10.753279 | G29: 8.4795355 | H29: 17.963178 | I29: 3.972159 | J29: 16.88408 | K29: 149.47002
B30: 40330 | C30: 51.881018 | D30: 22.273724 | E30: 22.294258 | F30: 11.718422 | G30: 8.4872153 | H30: 18.162769 | I30: 4.0162941 | J30: 17.071681 | K30: 155.90538
A31: 2010-11 | B31: 40422 | C31: 51.438638 | D31: 23.600665 | E31: 22.49867 | F31: 11.856725 | G31: 8.6561495 | H31: 19.490633 | I31: 3.9454431 | J31: 9.0140795 | K31: 150.501
B32: 40513 | C32: 46.705505 | D32: 20.455199 | E32: 23.481361 | F32: 10.840698 | G32: 8.7086681 | H32: 19.490633 | I32: 3.9454431 | J32: 9.0140795 | K32: 142.64159
B33: 40603 | C33: 50.231811 | D33: 18.714754 | E33: 22.015765 | F33: 10.125007 | G33: 8.5455754 | H33: 19.066924 | I33: 3.8596726 | J33: 8.8181213 | K33: 141.37763
B34: 40695 | C34: 50.028126 | D34: 22.683353 | E34: 22.979212 | F34: 11.193039 | G34: 8.3989252 | H34: 19.278779 | I34: 3.9025578 | J34: 8.9161004 | K34: 147.38009
A35: 2011-12 | B35: 40787 | C35: 51.064326 | D35: 24.665993 | E35: 23.010716 | F35: 11.635744 | G35: 8.6346954 | H35: 19.721091 | I35: 3.6005821 | J35: 2.1608059 | K35: 144.49395
B36: 40878 | C36: 48.612086 | D36: 20.841839 | E36: 23.311448 | F36: 11.437924 | G36: 7.8552057 | H36: 19.721091 | I36: 3.6005821 | J36: 2.1608059 | K36: 137.54098
B37: 40969 | C37: 50.620987 | D37: 19.370975 | E37: 22.454399 | F37: 10.558388 | G37: 7.7711681 | H37: 19.506731 | I37: 3.5614453 | J37: 2.1373189 | K37: 135.98141
B38: 41061 | C38: 48.740674 | D38: 22.87897 | E38: 22.711749 | F38: 11.371564 | G38: 7.7013325 | H38: 19.506731 | I38: 3.5614453 | J38: 2.1373189 | K38: 138.60978
A39: 2012-13 | B39: 41153 | C39: 47.086834 | D39: 25.312038 | E39: 23.136978 | F39: 11.658853 | G39: 7.5351058 | H39: 19.864662 | I39: 3.4954726 | J39: 4.7888214 | K39: 142.87876
B40: 41244 | C40: 45.594609 | D40: 22.325609 | E40: 23.763886 | F40: 11.560004 | G40: 7.5228865 | H40: 19.864662 | I40: 3.4954726 | J40: 4.7888214 | K40: 138.91595
B41: 41334 | C41: 47.187986 | D41: 20.295867 | E41: 22.725199 | F41: 10.81623 | G41: 7.3281374 | H41: 19.432822 | I41: 3.419484 | J41: 4.6847166 | K41: 135.89044
...

Sheet Data Table 1B
A1: ='Figure 1'!A1 -> Quarterly Update of Australia's National Greenhouse Gas Inventory | Figures and Tables for the December Quarter 2025
A2: Click here to return to contents page
A4: Data Table 1B: Seasonally adjusted emissions (Mt), by sector, by quarter, since 2004-05 (including preliminary March 2026)
A5: Year | B5: Quarter | C5: Energy | G5: Industrial Processes and Product Use | H5: Agriculture | I5: Waste | J5: Land Use, Land Use Change and Forestry (LULUCF) | K5: National Inventory Total
C6: Electricity | D6: Stationary Energy excl. electricity | E6: Transport | F6: Fugitive Emissions
A7: 2004-05 | B7: 38231 | C7: 48.865475 | D7: 19.988338 | E7: 20.335662 | F7: 10.406794 | G7: 7.3279655 | H7: 20.851753 | I7: 3.9501738 | J7: 19.455402 | K7: 151.18156
B8: 38322 | C8: 49.050492 | D8: 20.15839 | E8: 20.399833 | F8: 10.533554 | G8: 7.4673858 | H8: 20.761868 | I8: 3.937986 | J8: 19.343421 | K8: 151.65293
B9: 38412 | C9: 49.362296 | D9: 20.563014 | E9: 20.502138 | F9: 10.911701 | G9: 7.6372717 | H9: 20.577545 | I9: 3.9263722 | J9: 19.727764 | K9: 153.2081
B10: 38504 | C10: 49.398812 | D10: 20.531391 | E10: 20.567774 | F10: 10.73875 | G10: 7.6997637 | H10: 20.537783 | I10: 3.9454555 | J10: 18.203898 | K10: 151.62363
A11: 2005-06 | B11: 38596 | C11: 50.002402 | D11: 19.973565 | E11: 20.638063 | F11: 10.759007 | G11: 7.6192816 | H11: 20.537128 | I11: 3.8870567 | J11: 27.53879 | K11: 160.95529
B12: 38687 | C12: 50.426947 | D12: 19.993896 | E12: 20.70808 | F12: 10.849618 | G12: 7.5978516 | H12: 20.438301 | I12: 3.8734755 | J12: 27.277129 | K12: 161.1653
B13: 38777 | C13: 50.231293 | D13: 20.37556 | E13: 20.807231 | F13: 11.006216 | G13: 7.6494013 | H13: 20.262145 | I13: 3.8667753 | J13: 27.238298 | K13: 161.43692
B14: 38869 | C14: 50.534205 | D14: 20.193899 | E14: 20.898435 | F14: 10.953257 | G14: 7.7642943 | H14: 20.212341 | I14: 3.8836319 | J14: 25.961161 | K14: 160.40122
A15: 2006-07 | B15: 38961 | C15: 51.084158 | D15: 20.22394 | E15: 21.084953 | F15: 11.460832 | G15: 8.0475248 | H15: 19.687773 | I15: 3.9873014 | J15: 21.39157 | K15: 156.96805
B16: 39052 | C16: 50.977919 | D16: 20.325496 | E16: 21.180757 | F16: 11.664047 | G16: 8.1521103 | H16: 19.578265 | I16: 3.9731809 | J16: 20.993922 | K16: 156.8457
B17: 39142 | C17: 50.788617 | D17: 20.398681 | E17: 21.263236 | F17: 11.901558 | G17: 8.2045471 | H17: 19.426672 | I17: 3.9651225 | J17: 20.770251 | K17: 156.71868
B18: 39234 | C18: 51.068817 | D18: 20.516607 | E18: 21.381703 | F18: 11.866433 | G18: 8.2713842 | H18: 19.372279 | I18: 3.9801673 | J18: 19.495136 | K18: 155.95253
A19: 2007-08 | B19: 39326 | C19: 51.435619 | D19: 20.957087 | E19: 21.533995 | F19: 11.795892 | G19: 8.0239283 | H19: 18.957044 | I19: 4.1104159 | J19: 18.356328 | K19: 155.17031
B20: 39417 | C20: 51.380991 | D20: 20.905147 | E20: 21.635471 | F20: 11.404387 | G20: 8.0924752 | H20: 18.835048 | I20: 4.0946624 | J20: 17.746685 | K20: 154.09487
B21: 39508 | C21: 51.392958 | D21: 20.746218 | E21: 21.717823 | F21: 11.201393 | G21: 8.2503463 | H21: 18.939975 | I21: 4.1271965 | J21: 17.425589 | K21: 153.8015
B22: 39600 | C22: 51.50232 | D22: 21.251821 | E22: 21.86707 | F22: 11.762156 | G22: 8.316754 | H22: 18.672494 | I22: 4.0933313 | J22: 15.946254 | K22: 153.4122
A23: 2008-09 | B23: 39692 | C23: 52.935828 | D23: 21.303045 | E23: 21.549248 | F23: 11.421345 | G23: 8.2201091 | H23: 18.982004 | I23: 4.0827623 | J23: 16.808477 | K23: 155.30282
B24: 39783 | C24: 52.335492 | D24: 21.082834 | E24: 21.68191 | F24: 11.584001 | G24: 7.9691315 | H24: 18.864109 | I24: 4.0679172 | J24: 15.976533 | K24: 153.56193
B25: 39873 | C25: 52.991102 | D25: 20.012197 | E25: 21.776929 | F25: 11.435877 | G25: 7.0869835 | H25: 18.783992 | I25: 4.0456939 | J25: 15.22365 | K25: 151.35642
B26: 39965 | C26: 52.925256 | D26: 20.356381 | E26: 21.938374 | F26: 11.441267 | G26: 7.177604 | H26: 18.77433 | I26: 4.0530993 | J26: 13.890244 | K26: 150.55656
A27: 2009-10 | B27: 40057 | C27: 51.642296 | D27: 20.2477 | E27: 21.881548 | F27: 11.139664 | G27: 7.9102926 | H27: 18.302117 | I27: 4.0529227 | J27: 18.675171 | K27: 153.85171
B28: 40148 | C28: 50.676743 | D28: 20.672059 | E28: 22.073844 | F28: 11.422414 | G28: 8.3227366 | H28: 18.208999 | I28: 4.0367077 | J28: 17.607752 | K28: 153.02126
B29: 40238 | C29: 51.150487 | D29: 20.925724 | E29: 22.129669 | F29: 11.453691 | G29: 8.6121271 | H29: 18.181864 | I29: 4.0053272 | J29: 16.715658 | K29: 153.17455
B30: 40330 | C30: 51.191857 | D30: 21.239731 | E30: 22.346459 | F30: 11.460462 | G30: 8.6423496 | H30: 18.194646 | I30: 4.0072549 | J30: 15.390607 | K30: 152.47337
A31: 2010-11 | B31: 40422 | C31: 50.325298 | D31: 21.109308 | E31: 22.462675 | F31: 11.459512 | G31: 8.4649621 | H31: 19.386252 | I31: 3.9443715 | J31: 10.550267 | K31: 147.70265
B32: 40513 | C32: 49.112453 | D32: 21.234719 | E32: 22.744246 | F32: 10.797922 | G32: 8.6220708 | H32: 19.328397 | I32: 3.9265586 | J32: 9.3650581 | K32: 145.13142
B33: 40603 | C33: 49.373904 | D33: 21.405146 | E33: 22.72023 | F33: 10.806709 | G33: 8.6680814 | H33: 19.297755 | I33: 3.8904555 | J33: 8.6039701 | K33: 144.76625
B34: 40695 | C34: 49.501358 | D34: 21.706508 | E34: 23.074537 | F34: 10.961589 | G34: 8.5327946 | H34: 19.330763 | I34: 3.8883533 | J34: 7.1695711 | K34: 144.16547
A35: 2011-12 | B35: 40787 | C35: 50.313436 | D35: 22.207975 | E35: 22.930736 | F35: 11.230427 | G35: 8.4728071 | H35: 19.599153 | I35: 3.6031525 | J35: 3.8115967 | K35: 142.16928
